Workbook

Sheet Initial Inputs
A1: LAYNE NORTON'S PH3 PROGRAM
A3: MAX WEIGHT CALCULATOR
K4: lb
A5: For the following cells, please enter your most recent 1RM for | K5: kg
A6: the squat, bench press, and deadlift
A8: What is your weight tracked in (lb or kg)? | F8: lb
A10: Squat | B10: 320 | C10: =F8 -> lb
A11: Bench Press | B11: 260 | C11: =F8 -> lb
A12: Deadlift | B12: 420 | C12: =F8 -> lb
A14: Exercises labeled with "RIR" means you should choose a weight so you have
A15: the listed number of reps left in the tank (Repetitions in Reserve)
A17: Exercises labeled with "BFR" are lighter weight
A18: exercises with Blood Flow Restriction
A21: All credit for this program goes to Dr. Layne Norton
A22: This excel file is merely a way to make the program easily accessible

Sheet Accumulation Block
W2: ACCUMULATION BLOCK
AC4: ENTER WEIGHT BELOW | AP4: ENTER WEIGHT BELOW
AC5: Squat: | AE5: 320 | AG5: *Enter weight from the chart under Week 2 | AP5: Squat: | AR5: 320 | AT5: *Enter weight from the chart under Week 3
AC6: Bench: | AE6: 235 | AG6: to calculate numbers for Week 3 | AP6: Bench: | AR6: 235 | AT6: to calculate numbers for Week 4
A7: Week 1 | N7: Week 2 | AA7: Week 3 | AC7: Deadlift: | AE7: 420 | AN7: Week 4 | AP7: Deadlift: | AR7: 420
A9: Day 1 (Squat, Bench, Deadlift) | C9: Set 1 | E9: Set 2 | G9: Set 3 | I9: Set 4 | K9: Set 5 | N9: Day 8 (Squat, Bench, Deadlift) | P9: Set 1 | R9: Set 2 | T9: Set 3 | V9: Set 4 | X9: Set 5 | AA9: Day 15 (Squat, Bench, Deadlift) | AC9: Set 1 | AE9: Set 2 | AG9: Set 3 | AI9: Set 4 | AK9: Set 5 | AN9: Day 22 (Squat, Bench, Deadlift) | AP9: Set 1 | AR9: Set 2 | AT9: Set 3 | AV9: Set 4 | AX9: Set 5
A10: Squat | B10: Warm Up | C10: =IF(('Initial Inputs'!$F$8="kg"),MROUND(('Initial Inputs'!$B$10*0.725),2.5),MROUND(('Initial Inputs'!$B$10*0.725),5)) -> 230 | D10: x9 | E10: =C10 -> 230 | F10: x9 | N10: Squat | O10: Warm Up | P10: =IF(('Initial Inputs'!$F$8="kg"),MROUND(('Initial Inputs'!$B$10*0.725),2.5),MROUND(('Initial Inputs'!$B$10*0.725),5)) -> 230 | Q10: x9 | R10: =P10 -> 230 | S10: x9 | T10: =R10 -> 230 | U10: x9 | AA10: Squat | AB10: Warm Up | AC10: =IF(('Initial Inputs'!$F$8="kg"),MROUND(($AE$5*0.725),2.5),MROUND(($AE$5*0.725),5)) -> 230 | AD10: x9 | AE10: =AC10 -> 230 | AF10: x9 | AG10: =AE10 -> 230 | AH10: x9 | AN10: Squat | AO10: Warm Up | AP10: =IF(('Initial Inputs'!$F$8="kg"),MROUND(($AR$5*0.8),2.5),MROUND(($AR$5*0.8),5)) -> 255 | AQ10: x4 | AR10: =AP10 -> 255 | AS10: x4 | AT10: =AR10 -> 255 | AU10: x4 | AV10: =AT10 -> 255 | AW10: x4
A11: Bench Press | B11: Warm Up | C11: =IF(('Initial Inputs'!$F$8="kg"),MROUND(('Initial Inputs'!$B$11*0.725),2.5),MROUND(('Initial Inputs'!$B$11*0.725),5)) -> 190 | D11: x9 | E11: =C11 -> 190 | F11: x9 | N11: Bench Press | O11: Warm Up | P11: =IF(('Initial Inputs'!$F$8="kg"),MROUND(('Initial Inputs'!$B$11*0.725),2.5),MROUND(('Initial Inputs'!$B$11*0.725),5)) -> 190 | Q11: x9 | R11: =P11 -> 190 | S11: x9 | T11: =R11 -> 190 | U11: x9 | AA11: Bench Press | AB11: Warm Up | AC11: =IF(('Initial Inputs'!$F$8="kg"),MROUND(($AE$6*0.725),2.5),MROUND(($AE$6*0.725),5)) -> 170 | AD11: x9 | AE11: =AC11 -> 170 | AF11: x9 | AG11: =AE11 -> 170 | AH11: x9 | AN11: Bench Press | AO11: Warm Up | AP11: =IF(('Initial Inputs'!$F$8="kg"),MROUND(($AR$6*0.8),2.5),MROUND(($AR$6*0.8),5)) -> 190 | AQ11: x4 | AR11: =AP11 -> 190 | AS11: x4 | AT11: =AR11 -> 190 | AU11: x4 | AV11: =AT11 -> 190 | AW11: x4
A12: Deadlift | B12: Warm Up | C12: =IF(('Initial Inputs'!$F$8="kg"),MROUND(('Initial Inputs'!$B$12*0.725),2.5),MROUND(('Initial Inputs'!$B$12*0.725),5)) -> 305 | D12: x7 | E12: =C12 -> 305 | F12: x7 | N12: Deadlift | O12: Warm Up | P12: =IF(('Initial Inputs'!$F$8="kg"),MROUND(('Initial Inputs'!$B$12*0.725),2.5),MROUND(('Initial Inputs'!$B$12*0.725),5)) -> 305 | Q12: x7 | R12: =P12 -> 305 | S12: x7 | AA12: Deadlift | AB12: Warm Up | AC12: =IF(('Initial Inputs'!$F$8="kg"),MROUND(($AE$7*0.725),2.5),MROUND(($AE$7*0.725),5)) -> 305 | AD12: x7 | AE12: =AC12 -> 305 | AF12: x7 | AG12: =AE12 -> 305 | AH12: x7 | AN12: Deadlift | AO12: Warm Up | AP12: =IF(('Initial Inputs'!$F$8="kg"),MROUND(($AR$7*0.75),2.5),MROUND(($AR$7*0.75),5)) -> 315 | AQ12: x4 | AR12: =AP12 -> 315 | AS12: x4
A14: Day 2 (Upper Hypertrophy) | C14: Set 1 | E14: Set 2 | G14: Set 3 | I14: Set 4 | K14: Set 5 | N14: Day 9 (Upper Hypertrophy) | P14: Set 1 | R14: Set 2 | T14: Set 3 | V14: Set 4 | X14: Set 5 | AA14: Day 16 (Upper Hypertrophy) | AC14: Set 1 | AE14: Set 2 | AG14: Set 3 | AI14: Set 4 | AK14: Set 5 | AN14: Day 23 (Full-Body Hypertrophy) | AP14: Set 1 | AR14: Set 2 | AT14: Set 3 | AV14: Set 4 | AX14: Set 5
A15: Flat/Incline Dumbbell Press (3RIR) | B15: Warm Up | D15: x6-8 | F15: x6-8 | N15: Flat/Incline Dumbbell Press (3RIR) | O15: Warm Up | Q15: x6-8 | S15: x6-8 | AA15: Flat/Incline Dumbbell Press (3RIR) | AB15: Warm Up | AD15: x6-8 | AF15: x6-8 | AN15: Leg Extension (3RIR) | AO15: Warm Up | AQ15: x8-10 | AS15: x8-10
A16: Lat Pull-down/Weighted Pull-up (2RIR) | B16: Warm Up | D16: x6-8 | F16: x6-8 | H16: x6-8 | N16: Lat Pull-down/Weighted Pull-up (2RIR) | O16: Warm Up | Q16: x6-8 | S16: x6-8 | U16: x6-8 | AA16: Lat Pull-down/Weighted Pull-up (2RIR) | AB16: Warm Up | AD16: x6-8 | AF16: x6-8 | AH16: x6-8 | AN16: Leg Curl (3RIR) | AO16: Warm Up | AQ16: x8-10 | AS16: x8-10
A17: T-Bar Row/Machine Row (2RIR) | B17: Warm Up | D17: x6-8 | F17: x6-8 | N17: T-Bar Row/Machine Row (2RIR) | O17: Warm Up | Q17: x6-8 | S17: x6-8 | AA17: T-Bar Row/Machine Row (2RIR) | AB17: Warm Up | AD17: x6-8 | AF17: x6-8 | AN17: Calf Raise (1RIR) | AO17: Warm Up | AQ17: x6-8 | AS17: x6-8 | AU17: x6-8 | AW17: x6-8
A18: Seated Military Press (3RIR) | B18: Warm Up | D18: x5-7 | F18: x5-7 | N18: Seated Military Press (3RIR) | O18: Warm Up | Q18: x5-7 | S18: x5-7 | AA18: Seated Military Press (3RIR) | AB18: Warm Up | AD18: x5-7 | AF18: x5-7 | AN18: Flat/Incline Dumbbell Press (3RIR) | AO18: Warm Up | AQ18: x6-8 | AS18: x6-8
A19: Dumbbell/EZ-Bar Curl (1RIR) | B19: Warm Up | D19: x6-8 | F19: x6-8 | H19: x6-8 | J19: x6-8 | L19: x6-8 | N19: Dumbbell/EZ-Bar Curl (1RIR) | O19: Warm Up | Q19: x6-8 | S19: x6-8 | U19: x6-8 | W19: x6-8 | Y19: x6-8 | AA19: Dumbbell/EZ-Bar Curl (1RIR) | AB19: Warm Up | AD19: x6-8 | AF19: x6-8 | AH19: x6-8 | AJ19: x6-8 | AL19: x6-8 | AN19: Lat Pull-down/Weighted Pull-up (2RIR) | AO19: Warm Up | AQ19: x6-8 | AS19: x6-8 | AU19: x6-8
A20: BFR Machine Bicep Curl | B20: Warm Up | D20: x20 | F20: x10 | H20: x10 | J20: x10 | N20: BFR Machine Bicep Curl | O20: Warm Up | Q20: x20 | S20: x10 | U20: x10 | W20: x10 | AA20: BFR Machine Bicep Curl | AB20: Warm Up | AD20: x20 | AF20: x10 | AH20: x10 | AJ20: x10 | AN20: T-Bar Row/Machine Row (2RIR) | AO20: Warm Up | AQ20: x6-8 | AS20: x6-8
A21: EZ-Bar Skullcrusher/Tricep Push-down (1RIR) | B21: Warm Up | D21: x6-8 | F21: x6-8 | H21: x6-8 | J21: x6-8 | L21: x6-8 | N21: EZ-Bar Skullcrusher/Tricep Push-down (1RIR) | O21: Warm Up | Q21: x6-8 | S21: x6-8 | U21: x6-8 | W21: x6-8 | Y21: x6-8 | AA21: EZ-Bar Skullcrusher/Tricep Push-down (1RIR) | AB21: Warm Up | AD21: x6-8 | AF21: x6-8 | AH21: x6-8 | AJ21: x6-8 | AL21: x6-8 | AN21: Seated Military Press (3RIR) | AO21: Warm Up | AQ21: x5-7 | AS21: x5-7
A22: BFR Skullcrusher/Cable Tricep Push-down | B22: Warm Up | D22: x20 | F22: x10 | H22: x10 | J22: x10 | N22: BFR Skullcrusher/Cable Tricep Push-down | O22: Warm Up | Q22: x20 | S22: x10 | U22: x10 | W22: x10 | AA22: BFR Skullcrusher/Cable Tricep Push-down | AB22: Warm Up | AD22: x20 | AF22: x10 | AH22: x10 | AJ22: x10 | AN22: Dumbbell/EZ-Bar Curl | AO22: Warm Up | AQ22: x6-8 | AS22: x6-8 | AU22: x6-8 | AW22: x6-8 | AY22: x6-8
AN23: BFR Machine Bicep Curl | AO23: Warm Up | AQ23: x20 | AS23: x10 | AU23: x10 | AW23: x10
A24: Day 3 (Squat, Bench, Legs) | C24: Set 1 | E24: Set 2 | G24: Set 3 | I24: Set 4 | K24: Set 5 | N24: Day 10 (Squat, Bench, Legs) | P24: Set 1 | R24: Set 2 | T24: Set 3 | V24: Set 4 | X24: Set 5 | AA24: Day 17 (Squat, Bench, Legs) | AC24: Set 1 | AE24: Set 2 | AG24: Set 3 | AI24: Set 4 | AK24: Set 5 | AN24: EZ-Bar Skullcrusher/Tricep Push-down (1RIR) | AO24: Warm Up | AQ24: x6-8 | AS24: x6-8 | AU24: x6-8 | AW24: x6-8 | AY24: x6-8
A25: Squat | B25: Warm Up | C25: =IF(('Initial Inputs'!$F$8="kg"),MROUND(('Initial Inputs'!$B$10*0.775),2.5),MROUND(('Initial Inputs'!$B$10*0.775),5)) -> 250 | D25: x7 | E25: =C25 -> 250 | F25: x7 | G25: =E25 -> 250 | H25: x7 | N25: Squat | O25: Warm Up | P25: =IF(('Initial Inputs'!$F$8="kg"),MROUND(('Initial Inputs'!$B$10*0.775),2.5),MROUND(('Initial Inputs'!$B$10*0.775),5)) -> 250 | Q25: x7 | R25: =P25 -> 250 | S25: x7 | T25: =R25 -> 250 | U25: x7 | AA25: Squat | AB25: Warm Up | AC25: =IF(('Initial Inputs'!$F$8="kg"),MROUND(($AE$5*0.775),2.5),MROUND(($AE$5*0.775),5)) -> 250 | AD25: x7 | AE25: =AC25 -> 250 | AF25: x7 | AG25: =AE25 -> 250 | AH25: x7 | AI25: =AG25 -> 250 | AJ25: x7 | AN25: BFR Skullcrusher/Cable Tricep Push-down | AO25: Warm Up | AQ25: x20 | AS25: x10 | AU25: x10 | AW25: x10
A26: Bench Press | B26: Warm Up | C26: =IF(('Initial Inputs'!$F$8="kg"),MROUND(('Initial Inputs'!$B$11*0.775),2.5),MROUND(('Initial Inputs'!$B$11*0.775),5)) -> 200 | D26: x7 | E26: =C26 -> 200 | F26: x7 | G26: =E26 -> 200 | H26: x7 | N26: Bench Press | O26: Warm Up | P26: =IF(('Initial Inputs'!$F$8="kg"),MROUND(('Initial Inputs'!$B$11*0.775),2.5),MROUND(('Initial Inputs'!$B$11*0.775),5)) -> 200 | Q26: x7 | R26: =P26 -> 200 | S26: x7 | T26: =R26 -> 200 | U26: x7 | AA26: Bench Press | AB26: Warm Up | AC26: =IF(('Initial Inputs'!$F$8="kg"),MROUND(($AE$6*0.775),2.5),MROUND(($AE$6*0.775),5)) -> 180 | AD26: x7 | AE26: =AC26 -> 180 | AF26: x7 | AG26: =AE26 -> 180 | AH26: x7 | AI26: =AG26 -> 180 | AJ26: x7
A27: Leg Extension (3RIR) | B27: Warm Up | D27: x8-10 | F27: x8-10 | N27: Leg Extension (3RIR) | O27: Warm Up | Q27: x8-10 | S27: x8-10 | AA27: Leg Extension (3RIR) | AB27: Warm Up | AD27: x8-10 | AF27: x8-10 | AN27: Day 24 (Squat, Bench, Deadlift) | AP27: Set 1 | AR27: Set 2 | AT27: Set 3 | AV27: Set 4 | AX27: Set 5
A28: Leg Curl (3 RIR) | B28: Warm Up | D28: x8-10 | F28: x8-10 | N28: Leg Curl (3 RIR) | O28: Warm Up | Q28: x8-10 | S28: x8-10 | AA28: Leg Curl (3 RIR) | AB28: Warm Up | AD28: x8-10 | AF28: x8-10 | AN28: Squat | AO28: Warm Up | AP28: =IF(('Initial Inputs'!$F$8="kg"),MROUND(($AR$5*0.7),2.5),MROUND(($AR$5*0.7),5)) -> 225 | AQ28: x5 | AR28: =AP28 -> 225 | AS28: x5 | AT28: =AR28 -> 225 | AU28: x5
A29: Reverse Hyperextension (Optional) | B29: Warm Up | D29: x10-15 | F29: x10-15 | H29: x10-15 | N29: Reverse Hyperextension (Optional) | O29: Warm Up | Q29: x10-15 | S29: x10-15 | U29: x10-15 | AA29: Reverse Hyperextension (Optional) | AB29: Warm Up | AD29: x10-15 | AF29: x10-15 | AH29: x10-15 | AN29: Bench Press | AO29: Warm Up | AP29: =IF(('Initial Inputs'!$F$8="kg"),MROUND(($AR$6*0.7),2.5),MROUND(($AR$6*0.7),5)) -> 165 | AQ29: x5 | AR29: =AP29 -> 165 | AS29: x5 | AT29: =AR29 -> 165 | AU29: x5
A30: Ukrainian Stallion (Optional) | B30: Warm Up | D30: x15-20 | F30: x15-20 | H30: x15-20 | N30: Ukrainian Stallion (Optional) | O30: Warm Up | Q30: x15-20 | S30: x15-20 | U30: x15-20 | AA30: Ukrainian Stallion (Optional) | AB30: Warm Up | AD30: x15-20 | AF30: x15-20 | AH30: x15-20 | AN30: Deadlift | AO30: Warm Up | AP30: =IF(('Initial Inputs'!$F$8="kg"),MROUND(($AR$7*0.75),2.5),MROUND(($AR$7*0.75),5)) -> 315 | AQ30: x4 | AR30: =AP30 -> 315 | AS30: x4
A31: Calf Raise (1RIR) | B31: Warm Up | D31: x6-8 | F31: x6-8 | H31: x6-8 | J31: x6-8 | N31: Calf Raise (1RIR) | O31: Warm Up | Q31: x6-8 | S31: x6-8 | U31: x6-8 | W31: x6-8 | AA31: Calf Raise (1RIR) | AB31: Warm Up | AD31: x6-8 | AF31: x6-8 | AH31: x6-8 | AJ31: x6-8
A32: BFR Calf Raise | B32: Warm Up | D32: x20 | F32: x10 | H32: x10 | J32: x10 | N32: BFR Calf Raise | O32: Warm Up | Q32: x20 | S32: x10 | U32: x10 | W32: x10 | AA32: BFR Calf Raise | AB32: Warm Up | AD32: x20 | AF32: x10 | AH32: x10 | AJ32: x10 | AN32: Day 25 (Rest/Active Recovery)
A34: Day 4 (Rest/Active Recovery) | N34: Day 11 (Rest/Active Recovery) | AA34: Day 18 (Rest/Active Recovery) | AN34: Day 26 (Rest/Active Recovery)
A36: Day 5 (Deadlift, Bench, Upper-Body) | C36: Set 1 | E36: Set 2 | G36: Set 3 | I36: Set 4 | K36: Set 5 | N36: Day 12 (Deadlift, Bench, Upper-Body) | P36: Set 1 | R36: Set 2 | T36: Set 3 | V36: Set 4 | X36: Set 5 | AA36: Day 19 (Deadlift, Bench, Upper-Body) | AC36: Set 1 | AE36: Set 2 | AG36: Set 3 | AI36: Set 4 | AK36: Set 5 | AN36: Day 27 (Rep Test) | AP36: Set 1 | AR36: Set 2 | AT36: Set 3 | AV36: Set 4 | AX36: Set 5
A37: Deadlift | B37: Warm Up | C37: =IF(('Initial Inputs'!$F$8="kg"),MROUND(('Initial Inputs'!$B$12*0.825),2.5),MROUND(('Initial Inputs'!$B$12*0.825),5)) -> 345 | D37: x4 | E37: =C37 -> 345 | F37: x4 | N37: Deadlift (AMRAP Set 3) | O37: Warm Up | P37: =IF(('Initial Inputs'!$F$8="kg"),MROUND(('Initial Inputs'!$B$12*0.825),2.5),MROUND(('Initial Inputs'!$B$12*0.825),5)) -> 345 | Q37: x4 | R37: =P37 -> 345 | S37: x4 | T37: =R37 -> 345 | U37: AMRAP | AA37: Deadlift (AMRAP Final Set) | AB37: Warm Up | AC37: =IF(('Initial Inputs'!$F$8="kg"),MROUND(($AE$7*0.825),2.5),MROUND(($AE$7*0.825),5)) -> 345 | AD37: x4 | AE37: =AC37 -> 345 | AF37: x4 | AG37: =AE37 -> 345 | AH37: AMRAP | AN37: Squat | AO37: Warm Up | AP37: =IF(('Initial Inputs'!$F$8="kg"),MROUND(('Initial Inputs'!$B$10*0.85),2.5),MROUND(('Initial Inputs'!$B$10*0.85),5)) -> 270 | AQ37: AMRAP
A38: Bench Press | B38: Warm Up | C38: =IF(('Initial Inputs'!$F$8="kg"),MROUND(('Initial Inputs'!$B$11*0.825),2.5),MROUND(('Initial Inputs'!$B$11*0.825),5)) -> 215 | D38: x3 | E38: =C38 -> 215 | F38: x3 | G38: =E38 -> 215 | H38: x3 | N38: Bench Press (AMRAP Set 4) | O38: Warm Up | P38: =IF(('Initial Inputs'!$F$8="kg"),MROUND(('Initial Inputs'!$B$11*0.825),2.5),MROUND(('Initial Inputs'!$B$11*0.825),5)) -> 215 | Q38: x5 | R38: =P38 -> 215 | S38: x5 | T38: =R38 -> 215 | U38: x5 | V38: =T38 -> 215 | W38: AMRAP | AA38: Bench Press (AMRAP Final Set) | AB38: Warm Up | AC38: =IF(('Initial Inputs'!$F$8="kg"),MROUND(($AE$6*0.825),2.5),MROUND(($AE$6*0.825),5)) -> 195 | AD38: x5 | AE38: =AC38 -> 195 | AF38: x5 | AG38: =AE38 -> 195 | AH38: x5 | AI38: =AG38 -> 195 | AJ38: AMRAP | AN38: Bench Press | AO38: Warm Up | AP38: =IF(('Initial Inputs'!$F$8="kg"),MROUND(('Initial Inputs'!$B$11*0.85),2.5),MROUND(('Initial Inputs'!$B$11*0.85),5)) -> 220 | AQ38: AMRAP
A39: Pec-Deck Fly/Cable Crossover (3RIR) | B39: Warm Up | D39: x12-15 | F39: x12-15 | N39: Pec-Deck Fly/Cable Crossover (3RIR) | O39: Warm Up | Q39: x12-15 | S39: x12-15 | AA39: Pec-Deck Fly/Cable Crossover (3RIR) | AB39: Warm Up | AD39: x12-15 | AF39: x12-15 | AN39: Deadlift | AO39: Warm Up | AP39: =IF(('Initial Inputs'!$F$8="kg"),MROUND(('Initial Inputs'!$B$12*0.85),2.5),MROUND(('Initial Inputs'!$B$12*0.85),5)) -> 355 | AQ39: AMRAP
A40: Cable/Machine Lat Pull-Down (2RIR) | B40: Warm Up | D40: x12-15 | F40: x12-15 | N40: Cable/Machine Lat Pull-Down (2RIR) | O40: Warm Up | Q40: x12-15 | S40: x12-15 | AA40: Cable/Machine Lat Pull-Down (2RIR) | AB40: Warm Up | AD40: x12-15 | AF40: x12-15
A41: Dumbbell/Machine Row (2RIR) | B41: Warm Up | D41: x12-15 | F41: x12-15 | N41: Dumbbell/Machine Row (2RIR) | O41: Warm Up | Q41: x12-15 | S41: x12-15 | AA41: Dumbbell/Machine Row (2RIR) | AB41: Warm Up | AD41: x12-15 | AF41: x12-15 | AN41: Day 28 (Rest)
A42: Lateral Raise (2RIR) | B42: Warm Up | D42: x12-15 | F42: x12-15 | N42: Lateral Raise (2RIR) | O42: Warm Up | Q42: x12-15 | S42: x12-15 | AA42: Lateral Raise (2RIR) | AB42: Warm Up | AD42: x12-15 | AF42: x12-15
A43: Machine Preacher/Concentration Curl (1RIR) | B43: Warm Up | D43: x12-15 | F43: x12-15 | H43: x12-15 | J43: x12-15 | L43: x12-15 | N43: Machine Preacher/Concentration Curl (1RIR) | O43: Warm Up | Q43: x12-15 | S43: x12-15 | U43: x12-15 | W43: x12-15 | Y43: x12-15 | AA43: Machine Preacher/Concentration Curl (1RIR) | AB43: Warm Up | AD43: x12-15 | AF43: x12-15 | AH43: x12-15 | AJ43: x12-15 | AL43: x12-15
A44: BFR Machine Bicep Curl (2 Cluster Sets) | B44: Warm Up | D44: x30 | F44: x15 | H44: x15 | J44: x15 | N44: BFR Machine Bicep Curl (2 Cluster Sets) | O44: Warm Up | Q44: x30 | S44: x15 | U44: x15 | W44: x15 | AA44: BFR Machine Bicep Curl (2 Cluster Sets) | AB44: Warm Up | AD44: x30 | AF44: x15 | AH44: x15 | AJ44: x15 | AO44: Estimated 1RMs for Intermediate Block
A45: Cable Tricep Push-down (1RIR) | B45: Warm Up | D45: x12-15 | F45: x12-15 | H45: x12-15 | N45: Cable Tricep Push-down (1RIR) | O45: Warm Up | Q45: x12-15 | S45: x12-15 | U45: x12-15 | AA45: Cable Tricep Push-down (1RIR) | AB45: Warm Up | AD45: x12-15 | AF45: x12-15 | AH45: x12-15
A46: BFR Tricep Push-down (2 Cluster Sets) | B46: Warm Up | D46: x30 | F46: x15 | H46: x15 | J46: x15 | N46: BFR Tricep Push-down (2 Cluster Sets) | O46: Warm Up | Q46: x30 | S46: x15 | U46: x15 | W46: x15 | AA46: BFR Tricep Push-down (2 Cluster Sets) | AB46: Warm Up | AD46: x30 | AF46: x15 | AH46: x15 | AJ46: x15 | AN46: # of Reps | AO46: 1-4 | AP46: 5 | AQ46: 6-7 | AR46: 8+
...

Sheet Intermediate Block
W2: INTERMEDIATE BLOCK
C4: ENTER WEIGHT BELOW | AC4: ENTER WEIGHT BELOW | AP4: ENTER WEIGHT BELOW
C5: Squat: | E5: 320 | G5: *Enter weight from the chart under Week 4 | AC5: Squat: | AE5: 325 | AG5: *Enter weight from the chart under Week 6 | AP5: Squat: | AR5: 340 | AT5: *Enter weight from the chart under Week 7
C6: Bench: | E6: 260 | G6: to calculate numbers for Week 5 | AC6: Bench: | AE6: 240 | AG6: to calculate numbers for Week 7 | AP6: Bench: | AR6: 265 | AT6: to calculate numbers for Week 8
A7: Week 5 | C7: Deadlift: | E7: 420 | N7: Week 6 | AA7: Week 7 | AC7: Deadlift: | AE7: 420 | AN7: Week 8 | AP7: Deadlift: | AR7: 430
A9: Day 29 (Squat, Bench, Deadlift) | C9: Set 1 | E9: Set 2 | G9: Set 3 | I9: Set 4 | K9: Set 5 | N9: Day 36 (Squat, Bench, Deadlift) | P9: Set 1 | R9: Set 2 | T9: Set 3 | V9: Set 4 | X9: Set 5 | AA9: Day 43 (Squat, Bench, Deadlift) | AC9: Set 1 | AE9: Set 2 | AG9: Set 3 | AI9: Set 4 | AK9: Set 5 | AN9: Day 50 (Squat, Bench, Deadlift) | AP9: Set 1 | AR9: Set 2 | AT9: Set 3 | AV9: Set 4 | AX9: Set 5
A10: Squat | B10: Warm Up | C10: =IF(('Initial Inputs'!$F$8="kg"),MROUND(($E$5*0.75),2.5),MROUND(($E$5*0.75),5)) -> 240 | D10: x8 | E10: =C10 -> 240 | F10: =D10 -> x8 | N10: Squat | O10: Warm Up | P10: =IF(('Initial Inputs'!$F$8="kg"),MROUND(($E$5*0.75),2.5),MROUND(($E$5*0.75),5)) -> 240 | Q10: x8 | R10: =P10 -> 240 | S10: =Q10 -> x8 | T10: =R10 -> 240 | U10: =S10 -> x8 | AA10: Squat | AB10: Warm Up | AC10: =IF(('Initial Inputs'!$F$8="kg"),MROUND(($AE$5*0.75),2.5),MROUND(($AE$5*0.75),5)) -> 245 | AD10: x8 | AE10: =AC10 -> 245 | AF10: =AD10 -> x8 | AG10: =AE10 -> 245 | AH10: =AF10 -> x8 | AI10: =AG10 -> 245 | AJ10: =AH10 -> x8 | AN10: Squat | AO10: Warm Up | AP10: =IF(('Initial Inputs'!$F$8="kg"),MROUND(($AR$5*0.825),2.5),MROUND(($AR$5*0.825),5)) -> 280 | AQ10: x3 | AR10: =AP10 -> 280 | AS10: =AQ10 -> x3 | AT10: =AR10 -> 280 | AU10: =AS10 -> x3 | AV10: =AT10 -> 280 | AW10: =AU10 -> x3 | AX10: =AV10 -> 280 | AY10: =AW10 -> x3
A11: Bench Press | B11: Warm Up | C11: =IF(('Initial Inputs'!$F$8="kg"),MROUND(($E$6*0.75),2.5),MROUND(($E$6*0.75),5)) -> 195 | D11: x8 | E11: =C11 -> 195 | F11: =D11 -> x8 | N11: Bench Press | O11: Warm Up | P11: =IF(('Initial Inputs'!$F$8="kg"),MROUND(($E$6*0.75),2.5),MROUND(($E$6*0.75),5)) -> 195 | Q11: x8 | R11: =P11 -> 195 | S11: =Q11 -> x8 | T11: =R11 -> 195 | U11: =S11 -> x8 | AA11: Bench Press | AB11: Warm Up | AC11: =IF(('Initial Inputs'!$F$8="kg"),MROUND(($AE$6*0.75),2.5),MROUND(($AE$6*0.75),5)) -> 180 | AD11: x8 | AE11: =AC11 -> 180 | AF11: =AD11 -> x8 | AG11: =AE11 -> 180 | AH11: =AF11 -> x8 | AI11: =AG11 -> 180 | AJ11: =AH11 -> x8 | AN11: Bench Press | AO11: Warm Up | AP11: =IF(('Initial Inputs'!$F$8="kg"),MROUND(($AR$6*0.825),2.5),MROUND(($AR$6*0.825),5)) -> 220 | AQ11: x5 | AR11: =AP11 -> 220 | AS11: =AQ11 -> x5 | AT11: =AR11 -> 220 | AU11: =AS11 -> x5 | AV11: =AT11 -> 220 | AW11: =AU11 -> x5 | AX11: =AV11 -> 220 | AY11: =AW11 -> x5
A12: Deadlift | B12: Warm Up | C12: =IF(('Initial Inputs'!$F$8="kg"),MROUND(($E$7*0.75),2.5),MROUND(($E$7*0.75),5)) -> 315 | D12: x6 | E12: =C12 -> 315 | F12: =D12 -> x6 | N12: Deadlift | O12: Warm Up | P12: =IF(('Initial Inputs'!$F$8="kg"),MROUND(($E$7*0.75),2.5),MROUND(($E$7*0.75),5)) -> 315 | Q12: x6 | R12: =P12 -> 315 | S12: =Q12 -> x6 | T12: =R12 -> 315 | U12: =S12 -> x6 | AA12: Deadlift | AB12: Warm Up | AC12: =IF(('Initial Inputs'!$F$8="kg"),MROUND(($AE$7*0.75),2.5),MROUND(($AE$7*0.75),5)) -> 315 | AD12: x6 | AE12: =AC12 -> 315 | AF12: =AD12 -> x6 | AG12: =AE12 -> 315 | AH12: =AF12 -> x6 | AI12: =AG12 -> 315 | AJ12: =AH12 -> x6 | AN12: Deadlift | AO12: Warm Up | AP12: =IF(('Initial Inputs'!$F$8="kg"),MROUND(($AR$7*0.775),2.5),MROUND(($AR$7*0.775),5)) -> 335 | AQ12: x3 | AR12: =AP12 -> 335 | AS12: =AQ12 -> x3 | AT12: =AR12 -> 335 | AU12: =AS12 -> x3
A14: Day 30 (Upper Hypertrophy) | C14: Set 1 | E14: Set 2 | G14: Set 3 | I14: Set 4 | K14: Set 5 | N14: Day 37 (Upper Hypertrophy) | P14: Set 1 | R14: Set 2 | T14: Set 3 | V14: Set 4 | X14: Set 5 | AA14: Day 44 (Upper Hypertrophy) | AC14: Set 1 | AE14: Set 2 | AG14: Set 3 | AI14: Set 4 | AK14: Set 5 | AN14: Day 51 (Full-Body Hypertrophy) | AP14: Set 1 | AR14: Set 2 | AT14: Set 3 | AV14: Set 4 | AX14: Set 5
A15: Flat/Incline Dumbbell Press (3RIR) | B15: Warm Up | D15: x6-8 | F15: x6-8 | N15: Flat/Incline Dumbbell Press (3RIR) | O15: Warm Up | Q15: x6-8 | S15: x6-8 | AA15: Flat/Incline Dumbbell Press (3RIR) | AB15: Warm Up | AD15: x6-8 | AF15: x6-8 | AN15: Leg Extension (3RIR) | AO15: Warm Up | AQ15: x8-10 | AS15: x8-10
A16: Lat Pull-down/Weighted Pull-up (2RIR) | B16: Warm Up | D16: x6-8 | F16: x6-8 | H16: x6-8 | N16: Lat Pull-down/Weighted Pull-up (2RIR) | O16: Warm Up | Q16: x6-8 | S16: x6-8 | U16: x6-8 | AA16: Lat Pull-down/Weighted Pull-up (2RIR) | AB16: Warm Up | AD16: x6-8 | AF16: x6-8 | AH16: x6-8 | AN16: Leg Curl (3RIR) | AO16: Warm Up | AQ16: x8-10 | AS16: x8-10
A17: T-Bar Row/Machine Row (2RIR) | B17: Warm Up | D17: x6-8 | F17: x6-8 | N17: T-Bar Row/Machine Row (2RIR) | O17: Warm Up | Q17: x6-8 | S17: x6-8 | AA17: T-Bar Row/Machine Row (2RIR) | AB17: Warm Up | AD17: x6-8 | AF17: x6-8 | AN17: Calf Raise (1RIR) | AO17: Warm Up | AQ17: x6-8 | AS17: x6-8 | AU17: x6-8 | AW17: x6-8
A18: Seated Military Press (3RIR) | B18: Warm Up | D18: x5-7 | F18: x5-7 | N18: Seated Military Press (3RIR) | O18: Warm Up | Q18: x5-7 | S18: x5-7 | AA18: Seated Military Press (3RIR) | AB18: Warm Up | AD18: x5-7 | AF18: x5-7 | AN18: Flat/Incline Dumbbell Press (3RIR) | AO18: Warm Up | AQ18: x6-8 | AS18: x6-8
A19: Dumbbell/EZ-Bar Curl (1RIR) | B19: Warm Up | D19: x6-8 | F19: x6-8 | H19: x6-8 | J19: x6-8 | L19: x6-8 | N19: Dumbbell/EZ-Bar Curl (1RIR) | O19: Warm Up | Q19: x6-8 | S19: x6-8 | U19: x6-8 | W19: x6-8 | Y19: x6-8 | AA19: Dumbbell/EZ-Bar Curl (1RIR) | AB19: Warm Up | AD19: x6-8 | AF19: x6-8 | AH19: x6-8 | AJ19: x6-8 | AL19: x6-8 | AN19: Lat Pull-down/Weighted Pull-up (2RIR) | AO19: Warm Up | AQ19: x6-8 | AS19: x6-8 | AU19: x6-8
A20: BFR Machine Bicep Curl | B20: Warm Up | D20: x20 | F20: x10 | H20: x10 | J20: x10 | N20: BFR Machine Bicep Curl | O20: Warm Up | Q20: x20 | S20: x10 | U20: x10 | W20: x10 | AA20: BFR Machine Bicep Curl | AB20: Warm Up | AD20: x20 | AF20: x10 | AH20: x10 | AJ20: x10 | AN20: T-Bar Row/Machine Row (2RIR) | AO20: Warm Up | AQ20: x6-8 | AS20: x6-8
A21: EZ-Bar Skullcrusher/Tricep Push-down (1RIR) | B21: Warm Up | D21: x6-8 | F21: x6-8 | H21: x6-8 | J21: x6-8 | L21: x6-8 | N21: EZ-Bar Skullcrusher/Tricep Push-down (1RIR) | O21: Warm Up | Q21: x6-8 | S21: x6-8 | U21: x6-8 | W21: x6-8 | Y21: x6-8 | AA21: EZ-Bar Skullcrusher/Tricep Push-down (1RIR) | AB21: Warm Up | AD21: x6-8 | AF21: x6-8 | AH21: x6-8 | AJ21: x6-8 | AL21: x6-8 | AN21: Seated Military Press (3RIR) | AO21: Warm Up | AQ21: x5-7 | AS21: x5-7
A22: BFR Skullcrusher/Cable Tricep Push-down | B22: Warm Up | D22: x20 | F22: x10 | H22: x10 | J22: x10 | N22: BFR Skullcrusher/Cable Tricep Push-down | O22: Warm Up | Q22: x20 | S22: x10 | U22: x10 | W22: x10 | AA22: BFR Skullcrusher/Cable Tricep Push-down | AB22: Warm Up | AD22: x20 | AF22: x10 | AH22: x10 | AJ22: x10 | AN22: Dumbbell/EZ-Bar Curl (1 RIR) | AO22: Warm Up | AQ22: x6-8 | AS22: x6-8 | AU22: x6-8 | AW22: x6-8 | AY22: x6-8
AN23: BFR Machine Bicep Curl | AO23: Warm Up | AQ23: x20 | AS23: x10 | AU23: x10 | AW23: x10
A24: Day 31 (Squat, Bench, Legs) | C24: Set 1 | E24: Set 2 | G24: Set 3 | I24: Set 4 | K24: Set 5 | N24: Day 38 (Squat, Bench, Legs) | P24: Set 1 | R24: Set 2 | T24: Set 3 | V24: Set 4 | X24: Set 5 | AA24: Day 45 (Squat, Bench, Legs) | AC24: Set 1 | AE24: Set 2 | AG24: Set 3 | AI24: Set 4 | AK24: Set 5 | AN24: EZ-Bar Skullcrusher/Tricep Push-down (1RIR) | AO24: Warm Up | AQ24: x6-8 | AS24: x6-8 | AU24: x6-8 | AW24: x6-8 | AY24: x6-8
A25: Squat | B25: Warm Up | C25: =IF(('Initial Inputs'!$F$8="kg"),MROUND(($E$5*0.8),2.5),MROUND(($E$5*0.8),5)) -> 255 | D25: x6 | E25: =C25 -> 255 | F25: =D25 -> x6 | G25: =E25 -> 255 | H25: =F25 -> x6 | N25: Squat | O25: Warm Up | P25: =IF(('Initial Inputs'!$F$8="kg"),MROUND(($E$5*0.8),2.5),MROUND(($E$5*0.8),5)) -> 255 | Q25: x6 | R25: =P25 -> 255 | S25: =Q25 -> x6 | T25: =R25 -> 255 | U25: =S25 -> x6 | V25: =T25 -> 255 | W25: =U25 -> x6 | AA25: Squat | AB25: Warm Up | AC25: =IF(('Initial Inputs'!$F$8="kg"),MROUND(($AE$5*0.8),2.5),MROUND(($AE$5*0.8),5)) -> 260 | AD25: x6 | AE25: =AC25 -> 260 | AF25: =AD25 -> x6 | AG25: =AE25 -> 260 | AH25: =AF25 -> x6 | AI25: =AG25 -> 260 | AJ25: =AH25 -> x6 | AK25: =AI25 -> 260 | AL25: =AJ25 -> x6 | AN25: BFR Skullcrusher/Cable Tricep Push-down | AO25: Warm Up | AQ25: x20 | AS25: x10 | AU25: x10 | AW25: x10
A26: Bench Press | B26: Warm Up | C26: =IF(('Initial Inputs'!$F$8="kg"),MROUND(($E$6*0.8),2.5),MROUND(($E$6*0.8),5)) -> 210 | D26: x6 | E26: =C26 -> 210 | F26: =D26 -> x6 | G26: =E26 -> 210 | H26: =F26 -> x6 | N26: Bench Press | O26: Warm Up | P26: =IF(('Initial Inputs'!$F$8="kg"),MROUND(($E$6*0.8),2.5),MROUND(($E$6*0.8),5)) -> 210 | Q26: x6 | R26: =P26 -> 210 | S26: =Q26 -> x6 | T26: =R26 -> 210 | U26: =S26 -> x6 | V26: =T26 -> 210 | W26: =U26 -> x6 | AA26: Bench Press | AB26: Warm Up | AC26: =IF(('Initial Inputs'!$F$8="kg"),MROUND(($AE$6*0.8),2.5),MROUND(($AE$6*0.8),5)) -> 190 | AD26: x6 | AE26: =AC26 -> 190 | AF26: =AD26 -> x6 | AG26: =AE26 -> 190 | AH26: =AF26 -> x6 | AI26: =AG26 -> 190 | AJ26: =AH26 -> x6 | AK26: =AI26 -> 190 | AL26: =AJ26 -> x6
A27: Leg Extension (3RIR) | B27: Warm Up | D27: x8-10 | F27: x8-10 | N27: Leg Extension (3RIR) | O27: Warm Up | Q27: x8-10 | S27: x8-10 | AA27: Leg Extension (3RIR) | AB27: Warm Up | AD27: x8-10 | AF27: x8-10 | AN27: Day 52 (Squat, Bench, Deadlift) | AP27: Set 1 | AR27: Set 2 | AT27: Set 3 | AV27: Set 4 | AX27: Set 5
A28: Leg Curl (3 RIR) | B28: Warm Up | D28: x8-10 | F28: x8-10 | N28: Leg Curl (3 RIR) | O28: Warm Up | Q28: x8-10 | S28: x8-10 | AA28: Leg Curl (3 RIR) | AB28: Warm Up | AD28: x8-10 | AF28: x8-10 | AN28: Squat | AO28: Warm Up | AP28: =IF(('Initial Inputs'!$F$8="kg"),MROUND(($AR$5*0.7),2.5),MROUND(($AR$5*0.7),5)) -> 240 | AQ28: x4 | AR28: =AP28 -> 240 | AS28: =AQ28 -> x4 | AT28: =AR28 -> 240 | AU28: =AS28 -> x4 | AV28: =AT28 -> 240 | AW28: =AU28 -> x4
A29: Reverse Hyperextension (Optional) | B29: Warm Up | D29: x10-15 | F29: x10-15 | H29: x10-15 | N29: Reverse Hyperextension (Optional) | O29: Warm Up | Q29: x10-15 | S29: x10-15 | U29: x10-15 | AA29: Reverse Hyperextension (Optional) | AB29: Warm Up | AD29: x10-15 | AF29: x10-15 | AH29: x10-15 | AN29: Bench Press | AO29: Warm Up | AP29: =IF(('Initial Inputs'!$F$8="kg"),MROUND(($AR$6*0.7),2.5),MROUND(($AR$6*0.7),5)) -> 185 | AQ29: x4 | AR29: =AP29 -> 185 | AS29: =AQ29 -> x4 | AT29: =AR29 -> 185 | AU29: =AS29 -> x4 | AV29: =AT29 -> 185 | AW29: =AU29 -> x4
A30: Ukrainian Stallion (Optional) | B30: Warm Up | D30: x15-20 | F30: x15-20 | H30: x15-20 | N30: Ukrainian Stallion (Optional) | O30: Warm Up | Q30: x15-20 | S30: x15-20 | U30: x15-20 | AA30: Ukrainian Stallion (Optional) | AB30: Warm Up | AD30: x15-20 | AF30: x15-20 | AH30: x15-20 | AN30: Deadlift | AO30: Warm Up | AP30: =IF(('Initial Inputs'!$F$8="kg"),MROUND(($AR$7*0.7),2.5),MROUND(($AR$7*0.7),5)) -> 300 | AQ30: x4 | AR30: =AP30 -> 300 | AS30: =AQ30 -> x4 | AT30: =AR30 -> 300 | AU30: =AS30 -> x4
A31: Calf Raise (1RIR) | B31: Warm Up | D31: x6-8 | F31: x6-8 | H31: x6-8 | J31: x6-8 | N31: Calf Raise (1RIR) | O31: Warm Up | Q31: x6-8 | S31: x6-8 | U31: x6-8 | W31: x6-8 | AA31: Calf Raise (1RIR) | AB31: Warm Up | AD31: x6-8 | AF31: x6-8 | AH31: x6-8 | AJ31: x6-8
A32: BFR Calf Raise | B32: Warm Up | D32: x20 | F32: x10 | H32: x10 | J32: x10 | N32: BFR Calf Raise | O32: Warm Up | Q32: x20 | S32: x10 | U32: x10 | W32: x10 | AA32: BFR Calf Raise | AB32: Warm Up | AD32: x20 | AF32: x10 | AH32: x10 | AJ32: x10 | AN32: Day 53 (Rest/Active Recovery)
A34: Day 32 (Rest/Active Recovery) | N34: Day 39 (Rest/Active Recovery) | AA34: Day 46 (Rest/Active Recovery) | AN34: Day 54 (Rest/Active Recovery)
A36: Day 33 (Deadlift, Bench, Upper-Body) | C36: Set 1 | E36: Set 2 | G36: Set 3 | I36: Set 4 | K36: Set 5 | N36: Day 40 (Deadlift, Bench, Upper-Body) | P36: Set 1 | R36: Set 2 | T36: Set 3 | V36: Set 4 | X36: Set 5 | AA36: Day 47 (Deadlift, Bench, Upper-Body) | AC36: Set 1 | AE36: Set 2 | AG36: Set 3 | AI36: Set 4 | AK36: Set 5 | AN36: Day 55 (Rep Test) | AP36: Set 1 | AR36: Set 2 | AT36: Set 3 | AV36: Set 4 | AX36: Set 5
A37: Deadlift | B37: Warm Up | C37: =IF(('Initial Inputs'!$F$8="kg"),MROUND(($E$7*0.85),2.5),MROUND(($E$7*0.85),5)) -> 355 | D37: x3 | E37: =C37 -> 355 | F37: =D37 -> x3 | G37: =E37 -> 355 | H37: =F37 -> x3 | N37: Deadlift (AMRAP Set 3) | O37: Warm Up | P37: =IF(('Initial Inputs'!$F$8="kg"),MROUND(($E$7*0.85),2.5),MROUND(($E$7*0.85),5)) -> 355 | Q37: x3 | R37: =P37 -> 355 | S37: =Q37 -> x3 | T37: =R37 -> 355 | U37: =S37 -> x3 | V37: =T37 -> 355 | W37: AMRAP | AA37: Deadlift (AMRAP Final Set) | AB37: Warm Up | AC37: =IF(('Initial Inputs'!$F$8="kg"),MROUND(($AE$7*0.85),2.5),MROUND(($AE$7*0.85),5)) -> 355 | AD37: x3 | AE37: =AC37 -> 355 | AF37: =AD37 -> x3 | AG37: =AE37 -> 355 | AH37: =AF37 -> x3 | AI37: =AG37 -> 355 | AJ37: =AH37 -> x3 | AK37: =AI37 -> 355 | AL37: AMRAP | AN37: Squat | AO37: Warm Up | AP37: =IF(('Initial Inputs'!$F$8="kg"),MROUND(($E$5*0.875),2.5),MROUND(($E$5*0.875),5)) -> 280 | AQ37: AMRAP
A38: Bench Press | B38: Warm Up | C38: =IF(('Initial Inputs'!$F$8="kg"),MROUND(($E$6*0.85),2.5),MROUND(($E$6*0.85),5)) -> 220 | D38: x4 | E38: =C38 -> 220 | F38: =D38 -> x4 | G38: =E38 -> 220 | H38: =F38 -> x4 | I38: =G38 -> 220 | J38: =H38 -> x4 | N38: Bench Press (AMRAP Set 4) | O38: Warm Up | P38: =IF(('Initial Inputs'!$F$8="kg"),MROUND(($E$6*0.85),2.5),MROUND(($E$6*0.85),5)) -> 220 | Q38: x4 | R38: =P38 -> 220 | S38: =Q38 -> x4 | T38: =R38 -> 220 | U38: =S38 -> x4 | V38: =T38 -> 220 | W38: =U38 -> x4 | X38: =V38 -> 220 | Y38: AMRAP | AA38: Bench Press (AMRAP Final Set) | AB38: Warm Up | AC38: =IF(('Initial Inputs'!$F$8="kg"),MROUND(($AE$6*0.85),2.5),MROUND(($AE$6*0.85),5)) -> 205 | AD38: x4 | AE38: =AC38 -> 205 | AF38: =AD38 -> x4 | AG38: =AE38 -> 205 | AH38: =AF38 -> x4 | AI38: =AG38 -> 205 | AJ38: =AH38 -> x4 | AK38: =AI38 -> 205 | AL38: AMRAP | AN38: Bench Press | AO38: Warm Up | AP38: =IF(('Initial Inputs'!$F$8="kg"),MROUND(($E$6*0.875),2.5),MROUND(($E$6*0.875),5)) -> 230 | AQ38: AMRAP
A39: Pec-Deck Fly/Cable Crossover (3RIR) | B39: Warm Up | D39: x12-15 | F39: x12-15 | N39: Pec-Deck Fly/Cable Crossover (3RIR) | O39: Warm Up | Q39: x12-15 | S39: x12-15 | AA39: Pec-Deck Fly/Cable Crossover (3RIR) | AB39: Warm Up | AD39: x12-15 | AF39: x12-15 | AN39: Deadlift | AO39: Warm Up | AP39: =IF(('Initial Inputs'!$F$8="kg"),MROUND(($E$7*0.875),2.5),MROUND(($E$7*0.875),5)) -> 370 | AQ39: AMRAP
A40: Cable/Machine Lat Pull-Down (2RIR) | B40: Warm Up | D40: x12-15 | F40: x12-15 | N40: Cable/Machine Lat Pull-Down (2RIR) | O40: Warm Up | Q40: x12-15 | S40: x12-15 | AA40: Cable/Machine Lat Pull-Down (2RIR) | AB40: Warm Up | AD40: x12-15 | AF40: x12-15
A41: Dumbbell/Machine Row (2RIR) | B41: Warm Up | D41: x12-15 | F41: x12-15 | N41: Dumbbell/Machine Row (2RIR) | O41: Warm Up | Q41: x12-15 | S41: x12-15 | AA41: Dumbbell/Machine Row (2RIR) | AB41: Warm Up | AD41: x12-15 | AF41: x12-15 | AN41: Day 56 (Rest)
A42: Lateral Raise (2RIR) | B42: Warm Up | D42: x12-15 | F42: x12-15 | N42: Lateral Raise (2RIR) | O42: Warm Up | Q42: x12-15 | S42: x12-15 | AA42: Lateral Raise (2RIR) | AB42: Warm Up | AD42: x12-15 | AF42: x12-15
A43: Machine Preacher/Concentration Curl (1RIR) | B43: Warm Up | D43: x12-15 | F43: x12-15 | H43: x12-15 | J43: x12-15 | L43: x12-15 | N43: Machine Preacher/Concentration Curl (1RIR) | O43: Warm Up | Q43: x12-15 | S43: x12-15 | U43: x12-15 | W43: x12-15 | Y43: x12-15 | AA43: Machine Preacher/Concentration Curl (1RIR) | AB43: Warm Up | AD43: x12-15 | AF43: x12-15 | AH43: x12-15 | AJ43: x12-15 | AL43: x12-15
A44: BFR Machine Bicep Curl (2 Cluster Sets) | B44: Warm Up | D44: x30 | F44: x15 | H44: x15 | J44: x15 | N44: BFR Machine Bicep Curl (2 Cluster Sets) | O44: Warm Up | Q44: x30 | S44: x15 | U44: x15 | W44: x15 | AA44: BFR Machine Bicep Curl (2 Cluster Sets) | AB44: Warm Up | AD44: x30 | AF44: x15 | AH44: x15 | AJ44: x15 | AO44: Estimated 1RMs for Intensity Block
A45: Cable Tricep Push-down (1RIR) | B45: Warm Up | D45: x12-15 | F45: x12-15 | H45: x12-15 | N45: Cable Tricep Push-down (1RIR) | O45: Warm Up | Q45: x12-15 | S45: x12-15 | U45: x12-15 | AA45: Cable Tricep Push-down (1RIR) | AB45: Warm Up | AD45: x12-15 | AF45: x12-15 | AH45: x12-15
A46: BFR Tricep Push-down (2 Cluster Sets) | B46: Warm Up | D46: x30 | F46: x15 | H46: x15 | J46: x15 | N46: BFR Tricep Push-down (2 Cluster Sets) | O46: Warm Up | Q46: x30 | S46: x15 | U46: x15 | W46: x15 | AA46: BFR Tricep Push-down (2 Cluster Sets) | AB46: Warm Up | AD46: x30 | AF46: x15 | AH46: x15 | AJ46: x15 | AN46: # of Reps | AO46: 1-2 | AP46: 3-4 | AQ46: 5-6 | AR46: 7+
...

Sheet Intensity Block
W2: INTENSITY BLOCK
C4: ENTER WEIGHT BELOW | AC4: ENTER WEIGHT BELOW | AP4: ENTER WEIGHT BELOW
C5: Squat: | E5: 340 | G5: *Enter weight from the chart under Week 8 | AC5: Squat: | AE5: 430 | AG5: *Enter weight from the chart under Week 10 | AP5: Squat: | AR5: 445 | AT5: *Enter weight from the chart under Week 11
C6: Bench: | E6: 265 | G6: to calculate numbers for Week 9 | AC6: Bench: | AE6: 315 | AG6: to calculate numbers for Week 11 | AP6: Bench: | AR6: 300 | AT6: to calculate numbers for Week 12
A7: Week 9 | C7: Deadlift: | E7: 430 | N7: Week 10 | AA7: Week 11 | AC7: Deadlift: | AE7: 480 | AN7: Week 12 | AP7: Deadlift: | AR7: 445
A9: Day 57 (Squat, Bench, Deadlift) | C9: Set 1 | E9: Set 2 | G9: Set 3 | I9: Set 4 | K9: Set 5 | N9: Day 64 (Squat, Bench, Deadlift) | P9: Set 1 | R9: Set 2 | T9: Set 3 | V9: Set 4 | X9: Set 5 | AA9: Day 71 (Squat, Bench, Deadlift) | AC9: Set 1 | AE9: Set 2 | AG9: Set 3 | AI9: Set 4 | AK9: Set 5 | AN9: Day 78 (Squat, Bench, Deadlift) | AP9: Set 1 | AR9: Set 2 | AT9: Set 3 | AV9: Set 4 | AX9: Set 5 | AZ9: Set 6
A10: Squat | B10: Warm Up | C10: =IF(('Initial Inputs'!$F$8="kg"),MROUND(($E$5*0.775),2.5),MROUND(($E$5*0.775),5)) -> 265 | D10: x7 | E10: =C10 -> 265 | F10: =D10 -> x7 | G10: =E10 -> 265 | H10: =F10 -> x7 | N10: Squat | O10: Warm Up | P10: =IF(('Initial Inputs'!$F$8="kg"),MROUND(($E$5*0.775),2.5),MROUND(($E$5*0.775),5)) -> 265 | Q10: x7 | R10: =P10 -> 265 | S10: =Q10 -> x7 | T10: =R10 -> 265 | U10: =S10 -> x7 | V10: =T10 -> 265 | W10: =U10 -> x7 | AA10: Squat | AB10: Warm Up | AC10: =IF(('Initial Inputs'!$F$8="kg"),MROUND(($AE$5*0.775),2.5),MROUND(($AE$5*0.775),5)) -> 335 | AD10: x7 | AE10: =AC10 -> 335 | AF10: =AD10 -> x7 | AG10: =AE10 -> 335 | AH10: =AF10 -> x7 | AI10: =AG10 -> 335 | AJ10: =AH10 -> x7 | AK10: =AI10 -> 335 | AL10: =AJ10 -> x7 | AN10: Squat | AO10: Warm Up | AP10: =IF(('Initial Inputs'!$F$8="kg"),MROUND(($AR$5*0.775),2.5),MROUND(($AR$5*0.775),5)) -> 345 | AQ10: x7 | AR10: =AP10 -> 345 | AS10: =AQ10 -> x7 | AT10: =AR10 -> 345 | AU10: =AS10 -> x7 | AV10: =AT10 -> 345 | AW10: =AU10 -> x7 | AX10: =AV10 -> 345 | AY10: =AW10 -> x7 | ... BA10: =AY10 -> x7
A11: Bench Press | B11: Warm Up | C11: =IF(('Initial Inputs'!$F$8="kg"),MROUND(($E$6*0.775),2.5),MROUND(($E$6*0.775),5)) -> 205 | D11: x7 | E11: =C11 -> 205 | F11: =D11 -> x7 | G11: =E11 -> 205 | H11: =F11 -> x7 | N11: Bench Press | O11: Warm Up | P11: =IF(('Initial Inputs'!$F$8="kg"),MROUND(($E$6*0.775),2.5),MROUND(($E$6*0.775),5)) -> 205 | Q11: x7 | R11: =P11 -> 205 | S11: =Q11 -> x7 | T11: =R11 -> 205 | U11: =S11 -> x7 | V11: =T11 -> 205 | W11: =U11 -> x7 | AA11: Bench Press | AB11: Warm Up | AC11: =IF(('Initial Inputs'!$F$8="kg"),MROUND(($AE$6*0.775),2.5),MROUND(($AE$6*0.775),5)) -> 245 | AD11: x7 | AE11: =AC11 -> 245 | AF11: =AD11 -> x7 | AG11: =AE11 -> 245 | AH11: =AF11 -> x7 | AI11: =AG11 -> 245 | AJ11: =AH11 -> x7 | AK11: =AI11 -> 245 | AL11: =AJ11 -> x7 | AN11: Bench Press | AO11: Warm Up | AP11: =IF(('Initial Inputs'!$F$8="kg"),MROUND(($AR$6*0.775),2.5),MROUND(($AR$6*0.775),5)) -> 235 | AQ11: x7 | AR11: =AP11 -> 235 | AS11: =AQ11 -> x7 | AT11: =AR11 -> 235 | AU11: =AS11 -> x7 | AV11: =AT11 -> 235 | AW11: =AU11 -> x7 | AX11: =AV11 -> 235 | AY11: =AW11 -> x7 | ... BA11: =AY11 -> x7
A12: Deadlift | B12: Warm Up | C12: =IF(('Initial Inputs'!$F$8="kg"),MROUND(($E$7*0.775),2.5),MROUND(($E$7*0.775),5)) -> 335 | D12: x5 | E12: =C12 -> 335 | F12: =D12 -> x5 | G12: =E12 -> 335 | H12: =F12 -> x5 | N12: Deadlift | O12: Warm Up | P12: =IF(('Initial Inputs'!$F$8="kg"),MROUND(($E$7*0.775),2.5),MROUND(($E$7*0.775),5)) -> 335 | Q12: x5 | R12: =P12 -> 335 | S12: =Q12 -> x5 | T12: =R12 -> 335 | U12: =S12 -> x5 | V12: =T12 -> 335 | W12: =U12 -> x5 | AA12: Deadlift | AB12: Warm Up | AC12: =IF(('Initial Inputs'!$F$8="kg"),MROUND(($AE$7*0.775),2.5),MROUND(($AE$7*0.775),5)) -> 370 | AD12: x5 | AE12: =AC12 -> 370 | AF12: =AD12 -> x5 | AG12: =AE12 -> 370 | AH12: =AF12 -> x5 | AI12: =AG12 -> 370 | AJ12: =AH12 -> x5 | AK12: =AI12 -> 370 | AL12: =AJ12 -> x5 | AN12: Deadlift | AO12: Warm Up | AP12: =IF(('Initial Inputs'!$F$8="kg"),MROUND(($AR$7*0.725),2.5),MROUND(($AR$7*0.725),5)) -> 325 | AQ12: x5 | AR12: =AP12 -> 325 | AS12: =AQ12 -> x5 | AT12: =AR12 -> 325 | AU12: =AS12 -> x5 | AV12: =AT12 -> 325 | AW12: =AU12 -> x5 | AX12: =AV12 -> 325 | AY12: =AW12 -> x5 | ... BA12: =AY12 -> x5
A14: Day 58 (Upper Hypertrophy) | C14: Set 1 | E14: Set 2 | G14: Set 3 | I14: Set 4 | K14: Set 5 | N14: Day 65 (Upper Hypertrophy) | P14: Set 1 | R14: Set 2 | T14: Set 3 | V14: Set 4 | X14: Set 5 | AA14: Day 72 (Upper Hypertrophy) | AC14: Set 1 | AE14: Set 2 | AG14: Set 3 | AI14: Set 4 | AK14: Set 5 | AN14: Day 79 (Upper Hypertrophy) | AP14: Set 1 | AR14: Set 2 | AT14: Set 3 | AV14: Set 4 | AX14: Set 5
A15: Flat/Incline Dumbbell Press (3RIR) | B15: Warm Up | D15: x6-8 | F15: x6-8 | N15: Flat/Incline Dumbbell Press (3RIR) | O15: Warm Up | Q15: x6-8 | S15: x6-8 | AA15: Flat/Incline Dumbbell Press (3RIR) | AB15: Warm Up | AD15: x6-8 | AF15: x6-8 | AN15: Flat/Incline Dumbbell Press (3RIR) | AO15: Warm Up | AQ15: x6-8 | AS15: x6-8
A16: Lat Pull-down/Weighted Pull-up (2RIR) | B16: Warm Up | D16: x6-8 | F16: x6-8 | H16: x6-8 | N16: Lat Pull-down/Weighted Pull-up (2RIR) | O16: Warm Up | Q16: x6-8 | S16: x6-8 | U16: x6-8 | AA16: Lat Pull-down/Weighted Pull-up (2RIR) | AB16: Warm Up | AD16: x6-8 | AF16: x6-8 | AH16: x6-8 | AN16: Lat Pull-down/Weighted Pull-up (2RIR) | AO16: Warm Up | AQ16: x6-8 | AS16: x6-8 | AU16: x6-8
A17: T-Bar Row/Machine Row (2RIR) | B17: Warm Up | D17: x6-8 | F17: x6-8 | N17: T-Bar Row/Machine Row (2RIR) | O17: Warm Up | Q17: x6-8 | S17: x6-8 | AA17: T-Bar Row/Machine Row (2RIR) | AB17: Warm Up | AD17: x6-8 | AF17: x6-8 | AN17: T-Bar Row/Machine Row (2RIR) | AO17: Warm Up | AQ17: x6-8 | AS17: x6-8
A18: Seated Military Press (3RIR) | B18: Warm Up | D18: x5-7 | F18: x5-7 | N18: Seated Military Press (3RIR) | O18: Warm Up | Q18: x5-7 | S18: x5-7 | AA18: Seated Military Press (3RIR) | AB18: Warm Up | AD18: x5-7 | AF18: x5-7 | AN18: Seated Military Press (3RIR) | AO18: Warm Up | AQ18: x5-7 | AS18: x5-7
A19: Dumbbell/EZ-Bar Curl (1RIR) | B19: Warm Up | D19: x6-8 | F19: x6-8 | H19: x6-8 | J19: x6-8 | L19: x6-8 | N19: Dumbbell/EZ-Bar Curl (1RIR) | O19: Warm Up | Q19: x6-8 | S19: x6-8 | U19: x6-8 | W19: x6-8 | Y19: x6-8 | AA19: Dumbbell/EZ-Bar Curl (1RIR) | AB19: Warm Up | AD19: x6-8 | AF19: x6-8 | AH19: x6-8 | AJ19: x6-8 | AL19: x6-8 | AN19: Dumbbell/EZ-Bar Curl (1RIR) | AO19: Warm Up | AQ19: x6-8 | AS19: x6-8 | AU19: x6-8 | AW19: x6-8 | AY19: x6-8
A20: BFR Machine Bicep Curl | B20: Warm Up | D20: x20 | F20: x10 | H20: x10 | J20: x10 | N20: BFR Machine Bicep Curl | O20: Warm Up | Q20: x20 | S20: x10 | U20: x10 | W20: x10 | AA20: BFR Machine Bicep Curl | AB20: Warm Up | AD20: x20 | AF20: x10 | AH20: x10 | AJ20: x10 | AN20: BFR Machine Bicep Curl | AO20: Warm Up | AQ20: x20 | AS20: x10 | AU20: x10 | AW20: x10
A21: EZ-Bar Skullcrusher/Tricep Push-down (1RIR) | B21: Warm Up | D21: x6-8 | F21: x6-8 | H21: x6-8 | J21: x6-8 | L21: x6-8 | N21: EZ-Bar Skullcrusher/Tricep Push-down (1RIR) | O21: Warm Up | Q21: x6-8 | S21: x6-8 | U21: x6-8 | W21: x6-8 | Y21: x6-8 | AA21: EZ-Bar Skullcrusher/Tricep Push-down (1RIR) | AB21: Warm Up | AD21: x6-8 | AF21: x6-8 | AH21: x6-8 | AJ21: x6-8 | AL21: x6-8 | AN21: EZ-Bar Skullcrusher/Tricep Push-down (1RIR) | AO21: Warm Up | AQ21: x6-8 | AS21: x6-8 | AU21: x6-8 | AW21: x6-8 | AY21: x6-8
A22: BFR Skullcrusher/Cable Tricep Push-down | B22: Warm Up | D22: x20 | F22: x10 | H22: x10 | J22: x10 | N22: BFR Skullcrusher/Cable Tricep Push-down | O22: Warm Up | Q22: x20 | S22: x10 | U22: x10 | W22: x10 | AA22: BFR Skullcrusher/Cable Tricep Push-down | AB22: Warm Up | AD22: x20 | AF22: x10 | AH22: x10 | AJ22: x10 | AN22: BFR Skullcrusher/Cable Tricep Push-down | AO22: Warm Up | AQ22: x20 | AS22: x10 | AU22: x10 | AW22: x10
A24: Day 59 (Squat, Bench, Legs) | C24: Set 1 | E24: Set 2 | G24: Set 3 | I24: Set 4 | K24: Set 5 | N24: Day 66 (Squat, Bench, Legs) | P24: Set 1 | R24: Set 2 | T24: Set 3 | V24: Set 4 | X24: Set 5 | AA24: Day 73 (Squat, Bench, Legs) | AC24: Set 1 | AE24: Set 2 | AG24: Set 3 | AI24: Set 4 | AK24: Set 5 | AN24: Day 80 (Squat, Bench, Legs) | AP24: Set 1 | AR24: Set 2 | AT24: Set 3 | AV24: Set 4 | AX24: Set 5 | AZ24: Set 6
A25: Squat | B25: Warm Up | C25: =IF(('Initial Inputs'!$F$8="kg"),MROUND(($E$5*0.825),2.5),MROUND(($E$5*0.825),5)) -> 280 | D25: x5 | E25: =C25 -> 280 | F25: =D25 -> x5 | G25: =E25 -> 280 | H25: =F25 -> x5 | N25: Squat | O25: Warm Up | P25: =IF(('Initial Inputs'!$F$8="kg"),MROUND(($E$5*0.825),2.5),MROUND(($E$5*0.825),5)) -> 280 | Q25: x5 | R25: =P25 -> 280 | S25: =Q25 -> x5 | T25: =R25 -> 280 | U25: =S25 -> x5 | V25: =T25 -> 280 | W25: =U25 -> x5 | AA25: Squat | AB25: Warm Up | AC25: =IF(('Initial Inputs'!$F$8="kg"),MROUND(($AE$5*0.825),2.5),MROUND(($AE$5*0.825),5)) -> 355 | AD25: x5 | AE25: =AC25 -> 355 | AF25: =AD25 -> x5 | AG25: =AE25 -> 355 | AH25: =AF25 -> x5 | AI25: =AG25 -> 355 | AJ25: =AH25 -> x5 | AK25: =AI25 -> 355 | AL25: =AJ25 -> x5 | AN25: Squat | AO25: Warm Up | AP25: =IF(('Initial Inputs'!$F$8="kg"),MROUND(($AR$5*0.825),2.5),MROUND(($AR$5*0.825),5)) -> 365 | AQ25: x5 | AR25: =AP25 -> 365 | AS25: =AQ25 -> x5 | AT25: =AR25 -> 365 | AU25: =AS25 -> x5 | AV25: =AT25 -> 365 | AW25: =AU25 -> x5 | AX25: =AV25 -> 365 | AY25: =AW25 -> x5 | ... BA25: =AY25 -> x5
A26: Bench Press | B26: Warm Up | C26: =IF(('Initial Inputs'!$F$8="kg"),MROUND(($E$6*0.825),2.5),MROUND(($E$6*0.825),5)) -> 220 | D26: x5 | E26: =C26 -> 220 | F26: =D26 -> x5 | G26: =E26 -> 220 | H26: =F26 -> x5 | N26: Bench Press | O26: Warm Up | P26: =IF(('Initial Inputs'!$F$8="kg"),MROUND(($E$6*0.825),2.5),MROUND(($E$6*0.825),5)) -> 220 | Q26: x5 | R26: =P26 -> 220 | S26: =Q26 -> x5 | T26: =R26 -> 220 | U26: =S26 -> x5 | V26: =T26 -> 220 | W26: =U26 -> x5 | AA26: Bench Press | AB26: Warm Up | AC26: =IF(('Initial Inputs'!$F$8="kg"),MROUND(($AE$6*0.825),2.5),MROUND(($AE$6*0.825),5)) -> 260 | AD26: x5 | AE26: =AC26 -> 260 | AF26: =AD26 -> x5 | AG26: =AE26 -> 260 | AH26: =AF26 -> x5 | AI26: =AG26 -> 260 | AJ26: =AH26 -> x5 | AK26: =AI26 -> 260 | AL26: =AJ26 -> x5 | AN26: Bench Press | AO26: Warm Up | AP26: =IF(('Initial Inputs'!$F$8="kg"),MROUND(($AR$6*0.825),2.5),MROUND(($AR$6*0.825),5)) -> 250 | AQ26: x5 | AR26: =AP26 -> 250 | AS26: =AQ26 -> x5 | AT26: =AR26 -> 250 | AU26: =AS26 -> x5 | AV26: =AT26 -> 250 | AW26: =AU26 -> x5 | AX26: =AV26 -> 250 | AY26: =AW26 -> x5 | ... BA26: =AY26 -> x5
A27: Leg Extension (3RIR) | B27: Warm Up | D27: x8-10 | F27: x8-10 | N27: Leg Extension (3RIR) | O27: Warm Up | Q27: x8-10 | S27: x8-10 | AA27: Leg Extension (3RIR) | AB27: Warm Up | AD27: x8-10 | AF27: x8-10 | AN27: Leg Extension (3RIR) | AO27: Warm Up | AQ27: x8-10 | AS27: x8-10
A28: Leg Curl (3 RIR) | B28: Warm Up | D28: x8-10 | F28: x8-10 | N28: Leg Curl (3 RIR) | O28: Warm Up | Q28: x8-10 | S28: x8-10 | AA28: Leg Curl (3 RIR) | AB28: Warm Up | AD28: x8-10 | AF28: x8-10 | AN28: Leg Curl (3 RIR) | AO28: Warm Up | AQ28: x8-10 | AS28: x8-10
A29: Reverse Hyperextension (Optional) | B29: Warm Up | D29: x10-15 | F29: x10-15 | H29: x10-15 | N29: Reverse Hyperextension (Optional) | O29: Warm Up | Q29: x10-15 | S29: x10-15 | U29: x10-15 | AA29: Reverse Hyperextension (Optional) | AB29: Warm Up | AD29: x10-15 | AF29: x10-15 | AH29: x10-15 | AN29: Reverse Hyperextension (Optional) | AO29: Warm Up | AQ29: x10-15 | AS29: x10-15 | AU29: x10-15
A30: Ukrainian Stallion (Optional) | B30: Warm Up | D30: x15-20 | F30: x15-20 | H30: x15-20 | N30: Ukrainian Stallion (Optional) | O30: Warm Up | Q30: x15-20 | S30: x15-20 | U30: x15-20 | AA30: Ukrainian Stallion (Optional) | AB30: Warm Up | AD30: x15-20 | AF30: x15-20 | AH30: x15-20 | AN30: Ukrainian Stallion (Optional) | AO30: Warm Up | AQ30: x15-20 | AS30: x15-20 | AU30: x15-20
A31: Calf Raise (1RIR) | B31: Warm Up | D31: x6-8 | F31: x6-8 | H31: x6-8 | J31: x6-8 | N31: Calf Raise (1RIR) | O31: Warm Up | Q31: x6-8 | S31: x6-8 | U31: x6-8 | W31: x6-8 | AA31: Calf Raise (1RIR) | AB31: Warm Up | AD31: x6-8 | AF31: x6-8 | AH31: x6-8 | AJ31: x6-8 | AN31: Calf Raise (1RIR) | AO31: Warm Up | AQ31: x6-8 | AS31: x6-8 | AU31: x6-8 | AW31: x6-8
A32: BFR Calf Raise | B32: Warm Up | D32: x20 | F32: x10 | H32: x10 | J32: x10 | N32: BFR Calf Raise | O32: Warm Up | Q32: x20 | S32: x10 | U32: x10 | W32: x10 | AA32: BFR Calf Raise | AB32: Warm Up | AD32: x20 | AF32: x10 | AH32: x10 | AJ32: x10 | AN32: BFR Calf Raise | AO32: Warm Up | AQ32: x20 | AS32: x10 | AU32: x10 | AW32: x10
A34: Day 60 (Rest/Active Recovery) | N34: Day 67 (Rest/Active Recovery) | AA34: Day 74 (Rest/Active Recovery) | AN34: Day 81 (Rest/Active Recovery)
A36: Day 61 (Deadlift, Bench, Upper-Body) | C36: Set 1 | E36: Set 2 | G36: Set 3 | I36: Set 4 | K36: Set 5 | N36: Day 68 (Deadlift, Bench, Upper-Body) | P36: Set 1 | R36: Set 2 | T36: Set 3 | V36: Set 4 | X36: Set 5 | AA36: Day 75 (Deadlift, Bench, Upper-Body) | AC36: Set 1 | AE36: Set 2 | AG36: Set 3 | AI36: Set 4 | AK36: Set 5 | AN36: Day 82 (Deadlift, Bench, Upper-Body) | AP36: Set 1 | AR36: Set 2 | AT36: Set 3 | AV36: Set 4 | AX36: Set 5 | AZ36: Set 6
A37: Deadlift | B37: Warm Up | C37: =IF(('Initial Inputs'!$F$8="kg"),MROUND(($E$7*0.875),2.5),MROUND(($E$7*0.875),5)) -> 375 | D37: x2 | E37: =C37 -> 375 | F37: =D37 -> x2 | G37: =E37 -> 375 | H37: =F37 -> x2 | N37: Deadlift (AMRAP Set 3) | O37: Warm Up | P37: =IF(('Initial Inputs'!$F$8="kg"),MROUND(($E$7*0.875),2.5),MROUND(($E$7*0.875),5)) -> 375 | Q37: x2 | R37: =P37 -> 375 | S37: =Q37 -> x2 | T37: =R37 -> 375 | U37: =S37 -> x2 | V37: =T37 -> 375 | W37: AMRAP | AA37: Deadlift (AMRAP Final Set) | AB37: Warm Up | AC37: =IF(('Initial Inputs'!$F$8="kg"),MROUND(($AE$7*0.875),2.5),MROUND(($AE$7*0.875),5)) -> 420 | AD37: x2 | AE37: =AC37 -> 420 | AF37: =AD37 -> x2 | AG37: =AE37 -> 420 | AH37: =AF37 -> x2 | AI37: =AG37 -> 420 | AJ37: =AH37 -> x2 | AK37: =AI37 -> 420 | AL37: AMRAP | AN37: Deadlift (AMRAP Final Set) | AO37: Warm Up | AP37: =IF(('Initial Inputs'!$F$8="kg"),MROUND(($AR$7*0.875),2.5),MROUND(($AR$7*0.875),5)) -> 390 | AQ37: x2 | AR37: =AP37 -> 390 | AS37: =AQ37 -> x2 | AT37: =AR37 -> 390 | AU37: =AS37 -> x2 | AV37: =AT37 -> 390 | AW37: =AU37 -> x2 | AX37: =AV37 -> 390 | AY37: =AW37 -> x2 | AZ37: =AX37 -> 390 | BA37: AMRAP
A38: Bench Press | B38: Warm Up | C38: =IF(('Initial Inputs'!$F$8="kg"),MROUND(($E$6*0.875),2.5),MROUND(($E$6*0.875),5)) -> 230 | D38: x3 | E38: =C38 -> 230 | F38: =D38 -> x3 | G38: =E38 -> 230 | H38: =F38 -> x3 | I38: =G38 -> 230 | J38: =H38 -> x3 | N38: Bench Press (AMRAP Set 4) | O38: Warm Up | P38: =IF(('Initial Inputs'!$F$8="kg"),MROUND(($E$6*0.875),2.5),MROUND(($E$6*0.875),5)) -> 230 | Q38: x3 | R38: =P38 -> 230 | S38: =Q38 -> x3 | T38: =R38 -> 230 | U38: =S38 -> x3 | V38: =T38 -> 230 | W38: =U38 -> x3 | X38: =V38 -> 230 | Y38: AMRAP | AA38: Bench Press (AMRAP Final Set) | AB38: Warm Up | AC38: =IF(('Initial Inputs'!$F$8="kg"),MROUND(($AE$6*0.875),2.5),MROUND(($AE$6*0.875),5)) -> 275 | AD38: x3 | AE38: =AC38 -> 275 | AF38: =AD38 -> x3 | AG38: =AE38 -> 275 | AH38: =AF38 -> x3 | AI38: =AG38 -> 275 | AJ38: =AH38 -> x3 | AK38: =AI38 -> 275 | AL38: AMRAP | AN38: Bench Press (AMRAP Final Set) | AO38: Warm Up | AP38: =IF(('Initial Inputs'!$F$8="kg"),MROUND(($AR$6*0.875),2.5),MROUND(($AR$6*0.875),5)) -> 265 | AQ38: x3 | AR38: =AP38 -> 265 | AS38: =AQ38 -> x3 | AT38: =AR38 -> 265 | AU38: =AS38 -> x3 | AV38: =AT38 -> 265 | AW38: =AU38 -> x3 | AX38: =AV38 -> 265 | AY38: =AW38 -> x3 | AZ38: =AX38 -> 265 | BA38: AMRAP
A39: Pec-Deck Fly/Cable Crossover (3RIR) | B39: Warm Up | D39: x12-15 | F39: x12-15 | N39: Pec-Deck Fly/Cable Crossover (3RIR) | O39: Warm Up | Q39: x12-15 | S39: x12-15 | AA39: Pec-Deck Fly/Cable Crossover (3RIR) | AB39: Warm Up | AD39: x12-15 | AF39: x12-15 | AN39: Flat/Incline Dumbbell Press (3RIR) | AO39: Warm Up | AQ39: x6-8 | AS39: x6-8
A40: Cable/Machine Lat Pull-Down (2RIR) | B40: Warm Up | D40: x12-15 | F40: x12-15 | N40: Cable/Machine Lat Pull-Down (2RIR) | O40: Warm Up | Q40: x12-15 | S40: x12-15 | AA40: Cable/Machine Lat Pull-Down (2RIR) | AB40: Warm Up | AD40: x12-15 | AF40: x12-15 | AN40: Lat Pull-down/Weighted Pull-up (2RIR) | AO40: Warm Up | AQ40: x6-8 | AS40: x6-8 | AU40: x6-8
A41: Dumbbell/Machine Row (2RIR) | B41: Warm Up | D41: x12-15 | F41: x12-15 | N41: Dumbbell/Machine Row (2RIR) | O41: Warm Up | Q41: x12-15 | S41: x12-15 | AA41: Dumbbell/Machine Row (2RIR) | AB41: Warm Up | AD41: x12-15 | AF41: x12-15 | AN41: T-Bar Row/Machine Row (2RIR) | AO41: Warm Up | AQ41: x6-8 | AS41: x6-8
A42: Lateral Raise (2RIR) | B42: Warm Up | D42: x12-15 | F42: x12-15 | N42: Lateral Raise (2RIR) | O42: Warm Up | Q42: x12-15 | S42: x12-15 | AA42: Lateral Raise (2RIR) | AB42: Warm Up | AD42: x12-15 | AF42: x12-15 | AN42: Seated Military Press (3RIR) | AO42: Warm Up | AQ42: x5-7 | AS42: x5-7
A43: Machine Preacher/Concentration Curl (1RIR) | B43: Warm Up | D43: x12-15 | F43: x12-15 | H43: x12-15 | J43: x12-15 | L43: x12-15 | N43: Machine Preacher/Concentration Curl (1RIR) | O43: Warm Up | Q43: x12-15 | S43: x12-15 | U43: x12-15 | W43: x12-15 | Y43: x12-15 | AA43: Machine Preacher/Concentration Curl (1RIR) | AB43: Warm Up | AD43: x12-15 | AF43: x12-15 | AH43: x12-15 | AJ43: x12-15 | AL43: x12-15 | AN43: Dumbbell/EZ-Bar Curl (1RIR) | AO43: Warm Up | AQ43: x6-8 | AS43: x6-8 | AU43: x6-8 | AW43: x6-8
A44: BFR Machine Bicep Curl (2 Cluster Sets) | B44: Warm Up | D44: x30 | F44: x15 | H44: x15 | J44: x15 | N44: BFR Machine Bicep Curl (2 Cluster Sets) | O44: Warm Up | Q44: x30 | S44: x15 | U44: x15 | W44: x15 | AA44: BFR Machine Bicep Curl (2 Cluster Sets) | AB44: Warm Up | AD44: x30 | AF44: x15 | AH44: x15 | AJ44: x15 | AN44: BFR Machine Bicep Curl | AO44: Warm Up | AQ44: x20 | AS44: x10 | AU44: x10 | AW44: x10
A45: Cable Tricep Push-down (1RIR) | B45: Warm Up | D45: x12-15 | F45: x12-15 | H45: x12-15 | N45: Cable Tricep Push-down (1RIR) | O45: Warm Up | Q45: x12-15 | S45: x12-15 | U45: x12-15 | AA45: Cable Tricep Push-down (1RIR) | AB45: Warm Up | AD45: x12-15 | AF45: x12-15 | AH45: x12-15 | AJ45: x12-15 | AL45: x12-15 | AN45: EZ-Bar Skullcrusher/Tricep Push-down (1RIR) | AO45: Warm Up | AQ45: x6-8 | AS45: x6-8 | AU45: x6-8 | AW45: x6-8
A46: BFR Tricep Push-down (2 Cluster Sets) | B46: Warm Up | D46: x30 | F46: x15 | H46: x15 | J46: x15 | N46: BFR Tricep Push-down (2 Cluster Sets) | O46: Warm Up | Q46: x30 | S46: x15 | U46: x15 | W46: x15 | AN46: BFR Skullcrusher/Cable Tricep Push-down | AO46: Warm Up | AQ46: x20 | AS46: x10 | AU46: x10 | AW46: x10
A49: Day 62 (Squat, Legs) | C49: Set 1 | E49: Set 2 | G49: Set 3 | I49: Set 4 | K49: Set 5 | N49: Day 69 (Squat, Legs) | P49: Set 1 | R49: Set 2 | T49: Set 3 | V49: Set 4 | X49: Set 5 | AA49: Day 76 (Squat, Legs) | AC49: Set 1 | AE49: Set 2 | AG49: Set 3 | AI49: Set 4 | AK49: Set 5 | AN49: Day 83 (Squat, Legs) | AP49: Set 1 | AR49: Set 2 | AT49: Set 3 | AV49: Set 4 | AX49: Set 5 | AZ49: Set 6
...

Sheet Taper (Final Week)
A1: FINAL WEEK
C4: ENTER WEIGHT BELOW
C5: Squat: | E5: 420 | G5: *Enter weight from the chart under Week 12
C6: Bench: | E6: 285 | G6: to calculate numbers for Week 13
A7: Week 13 | C7: Deadlift: | E7: 425
A9: Day 85 (Squat, Bench, Deadlift) | C9: Set 1 | E9: Set 2 | G9: Set 3 | I9: Set 4 | K9: Set 5
A10: Squat | B10: Warm Up | C10: =IF(('Initial Inputs'!$F$8="kg"),MROUND(($E$5*0.825),2.5),MROUND(($E$5*0.825),5)) -> 345 | D10: x3 | E10: =C10 -> 345 | F10: =D10 -> x3 | G10: =E10 -> 345 | H10: =F10 -> x3 | I10: =G10 -> 345 | J10: =H10 -> x3 | K10: =I10 -> 345 | L10: =J10 -> x3
A11: Bench Press | B11: Warm Up | C11: =IF(('Initial Inputs'!$F$8="kg"),MROUND(($E$6*0.825),2.5),MROUND(($E$6*0.825),5)) -> 235 | D11: x3 | E11: =C11 -> 235 | F11: =D11 -> x3 | G11: =E11 -> 235 | H11: =F11 -> x3 | I11: =G11 -> 235 | J11: =H11 -> x3 | K11: =I11 -> 235 | L11: =J11 -> x3
A12: Deadlift | B12: Warm Up | C12: =IF(('Initial Inputs'!$F$8="kg"),MROUND(($E$7*0.775),2.5),MROUND(($E$7*0.775),5)) -> 330 | D12: x3 | E12: =C12 -> 330 | F12: =D12 -> x3 | G12: =E12 -> 330 | H12: =F12 -> x3
A15: Day 86 (Full Body Hypertrophy) | C15: Set 1 | E15: Set 2 | G15: Set 3 | I15: Set 4 | K15: Set 5
A16: Leg Extension (3RIR) | B16: Warm Up | D16: x8-10 | F16: =D16 -> x8-10
A17: Leg Curl (3RIR) | B17: Warm Up | D17: x8x10 | F17: =D17 -> x8x10
A18: Calf Raise (1 RIR) | B18: Warm Up | D18: x6-8 | F18: =D18 -> x6-8 | H18: =F18 -> x6-8 | J18: =H18 -> x6-8
A19: BFR Calf Raise | B19: Warm Up | D19: x20 | F19: x10 | H19: =F19 -> x10 | J19: =H19 -> x10
A20: Pec-Deck Fly/Cable Cross-Over (3 RIR) | B20: Warm Up | D20: x12-15 | F20: =D20 -> x12-15
A21: Lat Pull-Down (2 RIR) | B21: Warm Up | D21: x12-15 | F21: =D21 -> x12-15
A22: Dumbbell/Machine Row (2 RIR) | B22: Warm Up | D22: x12-15 | F22: =D22 -> x12-15
A23: Lateral Raise (2 RIR) | B23: Warm Up | D23: x12-15 | F23: =D23 -> x12-15
A24: Preacher/Concentration Curl (1 RIR) | B24: Warm Up | D24: x12-15 | F24: =D24 -> x12-15 | H24: =F24 -> x12-15 | J24: =H24 -> x12-15 | L24: =J24 -> x12-15
A25: BFR Machine Curl (2 Cluster Sets) | B25: Warm Up | D25: x30 | F25: x15 | H25: =F25 -> x15 | J25: =H25 -> x15
A26: Cable Tricep Push-Down (1 RIR) | B26: Warm Up | D26: x12-15 | F26: =D26 -> x12-15 | H26: =F26 -> x12-15 | J26: =H26 -> x12-15 | L26: =J26 -> x12-15
A29: Day 87 (Squat, Bench, Legs) | C29: Set 1 | E29: Set 2 | G29: Set 3 | I29: Set 4 | K29: Set 5
A30: Squat | B30: Warm Up | C30: =IF(('Initial Inputs'!$F$8="kg"),MROUND(($E$5*0.725),2.5),MROUND(($E$5*0.725),5)) -> 305 | D30: x4 | E30: =C30 -> 305 | F30: =D30 -> x4 | G30: =E30 -> 305 | H30: =F30 -> x4 | I30: =G30 -> 305 | J30: =H30 -> x4
A31: Bench Press | B31: Warm Up | C31: =IF(('Initial Inputs'!$F$8="kg"),MROUND(($E$6*0.725),2.5),MROUND(($E$6*0.725),5)) -> 205 | D31: x4 | E31: =C31 -> 205 | F31: =D31 -> x4 | G31: =E31 -> 205 | H31: =F31 -> x4 | I31: =G31 -> 205 | J31: =H31 -> x4
A32: Deadlift | B32: Warm Up | C32: =IF(('Initial Inputs'!$F$8="kg"),MROUND(($E$7*0.7),2.5),MROUND(($E$7*0.7),5)) -> 300 | D32: x3 | E32: =C32 -> 300 | F32: =D32 -> x3 | G32: =E32 -> 300 | H32: =F32 -> x3
A35: Day 88 (Rest)
A37: Day 89 (Rest)
A40: Day 90 (Testing) | C40: Attempt 1 | E40: Attempt 2 | G40: Attempt 3
A41: Squat | B41: Warm Up | C41: 90-94% | E41: 96-100% | G41: 100-104%
C42: =P42&" to "&Q42 -> 380 to 395 | E42: =S42&" to "&T42 -> 405 to 420 | G42: =V42&" to "&W42 -> 420 to 435 | P42: =IF(('Initial Inputs'!$F$8="kg"),MROUND(($E$5*0.9),2.5),MROUND(($E$5*0.9),5)) -> 380 | Q42: =IF(('Initial Inputs'!$F$8="kg"),MROUND(($E$5*0.94),2.5),MROUND(($E$5*0.94),5)) -> 395 | S42: =IF(('Initial Inputs'!$F$8="kg"),MROUND(($E$5*0.96),2.5),MROUND(($E$5*0.96),5)) -> 405 | T42: =IF(('Initial Inputs'!$F$8="kg"),MROUND(($E$5*1),2.5),MROUND(($E$5*1),5)) -> 420 | V42: =IF(('Initial Inputs'!$F$8="kg"),MROUND(($E$5*1),2.5),MROUND(($E$5*1),5)) -> 420 | W42: =IF(('Initial Inputs'!$F$8="kg"),MROUND(($E$5*1.04),2.5),MROUND(($E$5*1.04),5)) -> 435
A44: Bench Press | B44: Warm Up | C44: 90-94% | E44: 96-100% | G44: 100-104%
C45: =P45&" to "&Q45 -> 255 to 270 | E45: =S45&" to "&T45 -> 275 to 285 | G45: =V45&" to "&W45 -> 285 to 295 | P45: =IF(('Initial Inputs'!$F$8="kg"),MROUND(($E$6*0.9),2.5),MROUND(($E$6*0.9),5)) -> 255 | Q45: =IF(('Initial Inputs'!$F$8="kg"),MROUND(($E$6*0.94),2.5),MROUND(($E$6*0.94),5)) -> 270 | S45: =IF(('Initial Inputs'!$F$8="kg"),MROUND(($E$6*0.96),2.5),MROUND(($E$6*0.96),5)) -> 275 | T45: =IF(('Initial Inputs'!$F$8="kg"),MROUND(($E$6*1),2.5),MROUND(($E$6*1),5)) -> 285 | V45: =IF(('Initial Inputs'!$F$8="kg"),MROUND(($E$6*1),2.5),MROUND(($E$6*1),5)) -> 285 | W45: =IF(('Initial Inputs'!$F$8="kg"),MROUND(($E$6*1.04),2.5),MROUND(($E$6*1.04),5)) -> 295
A47: Deadlift | B47: Warm Up | C47: 90-94% | E47: 96-100% | G47: 100-104%
C48: =P48&" to "&Q48 -> 385 to 400 | E48: =S48&" to "&T48 -> 410 to 425 | G48: =V48&" to "&W48 -> 425 to 440 | P48: =IF(('Initial Inputs'!$F$8="kg"),MROUND(($E$7*0.9),2.5),MROUND(($E$7*0.9),5)) -> 385 | Q48: =IF(('Initial Inputs'!$F$8="kg"),MROUND(($E$7*0.94),2.5),MROUND(($E$7*0.94),5)) -> 400 | S48: =IF(('Initial Inputs'!$F$8="kg"),MROUND(($E$7*0.96),2.5),MROUND(($E$7*0.96),5)) -> 410 | T48: =IF(('Initial Inputs'!$F$8="kg"),MROUND(($E$7*1),2.5),MROUND(($E$7*1),5)) -> 425 | V48: =IF(('Initial Inputs'!$F$8="kg"),MROUND(($E$7*1),2.5),MROUND(($E$7*1),5)) -> 425 | W48: =IF(('Initial Inputs'!$F$8="kg"),MROUND(($E$7*1.04),2.5),MROUND(($E$7*1.04),5)) -> 440
A51: *Choose numbers between the two percentages given per attempt
A52: Ex: if your estimated 1RM on the deadlift is 500lbs, you will choose anything
A53: between the range of 450-470lbs for your first attempt
